Workbook

Sheet SEMANA 01
C1: REPORTE ESTADÍSTICO SEMANAL SSOMA | J1: CÓDIGO: | K1: SG-SSOMA-03
J2: REVISIÓN: | K2: 03
J3: FECHA: | K3: 46119
J4: PÁGINA: | K4: 01/06
A6: Obra / Proyecto:
A7: Empresa:
A8: Mes - Año: | G8: Semana N°: | I8: 1
A9: Residente de Obra: | G9: Supervisor SSOMA:
A11: HORAS HOMBRE TRABAJADAS
A13: INFORMACIÓN HHT | D13: TURNO DIURNO
D14: Lunes | E14: Martes | F14: Miércoles | G14: Jueves | H14: Viernes | I14: Sábado | J14: Domingo | K14: TOTAL SEMANAL
F15: 46113 | G15: =F15+1 -> 46114 | H15: =G15+1 -> 46115 | I15: =H15+1 -> 46116 | J15: =I15+1 -> 46117
A16: 1 | B16: Cantidad de personal obrero RUAG | D16: 0 | E16: 0 | F16: 0 | G16: 0 | H16: 0 | I16: 0 | J16: 0 | K16: =AVERAGE(F16:J16) -> 0
A17: 2 | B17: Cantidad de personal obrero SUBCONTRATISTA | D17: 0 | E17: 0 | F17: 0 | G17: 0 | H17: 0 | I17: 0 | J17: 0 | K17: =AVERAGE(F17:J17) -> 0
A18: 3 | B18: Cantidad de personal de STAFF RUAG | D18: 0 | E18: 0 | F18: 0 | G18: 0 | H18: 0 | I18: 0 | J18: 0 | K18: =AVERAGE(F18:J18) -> 0
A19: 4 | B19: Cantidad de personal de STAFF SUBCONTRATISTA | D19: 0 | E19: 0 | F19: 0 | G19: 0 | H19: 0 | I19: 0 | J19: 0 | K19: =AVERAGE(F19:J19) -> 0
A20: TOTAL TRABAJADORES RUAG | D20: =D16+D18 -> 0 | E20: =E16+E18 -> 0 | F20: =F16+F18 -> 0 | G20: =G16+G18 -> 0 | H20: =H16+H18 -> 0 | I20: =I16+I18 -> 0 | J20: =J16+J18 -> 0 | K20: =K16+K18 -> 0
A21: TOTAL TRABAJADORES SUBCONTRATISTA | D21: =D17+D19 -> 0 | E21: =E17+E19 -> 0 | F21: =F17+F19 -> 0 | G21: =G17+G19 -> 0 | H21: =H17+H19 -> 0 | I21: =I17+I19 -> 0 | J21: =J17+J19 -> 0 | K21: =K17+K19 -> 0
A22: 5 | B22: Total HH personal Obrero RUAG | D22: =D16*8.5 -> 0 | E22: =E16*8.5 -> 0 | F22: =F16*8.5 -> 0 | G22: =G16*8.5 -> 0 | H22: =H16*8.5 -> 0 | I22: =I16*5.5 -> 0 | J22: =J16*5.5 -> 0 | K22: =SUM(F22:J22) -> 0
A23: 6 | B23: Total HH personal Obrero SUBCONTRATISTA | D23: =D17*8.5 -> 0 | E23: =E17*8.5 -> 0 | F23: =F17*8.5 -> 0 | G23: =G17*8.5 -> 0 | H23: =H17*8.5 -> 0 | I23: =I17*5.5 -> 0 | J23: =J17*5.5 -> 0 | K23: =SUM(F23:J23) -> 0
A24: 7 | B24: Total HH personal STAFF RUAG | D24: =D18*8.5 -> 0 | E24: =E18*8.5 -> 0 | F24: =F18*8.5 -> 0 | G24: =G18*8.5 -> 0 | H24: =H18*8.5 -> 0 | I24: =I18*5.5 -> 0 | J24: =J18*5.5 -> 0 | K24: =SUM(F24:J24) -> 0
A25: 8 | B25: Total HH personal STAFF SUBCONTRATISTA | D25: =D19*8.5 -> 0 | E25: =E19*8.5 -> 0 | F25: =F19*8.5 -> 0 | G25: =G19*8.5 -> 0 | H25: =H19*8.5 -> 0 | I25: =I19*5.5 -> 0 | J25: =J19*5.5 -> 0 | K25: =SUM(F25:J25) -> 0
A26: TOTAL HH PRODUCIDAS RUAG | D26: =D22+D24 -> 0 | E26: =E22+E24 -> 0 | F26: =F22+F24 -> 0 | G26: =G22+G24 -> 0 | H26: =H22+H24 -> 0 | I26: =I22+I24 -> 0 | J26: =J22+J24 -> 0 | K26: =K22+K24 -> 0
A27: TOTAL HH PRODUCIDAS SUBCONTRATISTA | D27: =D23+D25 -> 0 | E27: =E23+E25 -> 0 | F27: =F23+F25 -> 0 | G27: =G23+G25 -> 0 | H27: =H23+H25 -> 0 | I27: =I23+I25 -> 0 | J27: =J23+J25 -> 0 | K27: =K23+K25 -> 0
A28: INFORMACIÓN HHT | D28: TURNO NOCTURNO
D29: Lunes | E29: Martes | F29: Miércoles | G29: Jueves | H29: Viernes | I29: Sábado | J29: Domingo | K29: TOTAL SEMANAL
F30: =F15 -> 46113 | G30: =G15 -> 46114 | H30: =H15 -> 46115 | I30: =I15 -> 46116 | J30: =J15 -> 46117
A31: 9 | B31: Cantidad de personal obrero RUAG | D31: 0 | E31: 0 | F31: 0 | G31: 0 | H31: 0 | I31: 0 | J31: 0 | K31: =AVERAGE(F31:J31) -> 0
A32: 10 | B32: Cantidad de personal obrero SUBCONTRATISTA | D32: 0 | E32: 0 | F32: 0 | G32: 0 | H32: 0 | I32: 0 | J32: 0 | K32: =AVERAGE(F32:J32) -> 0
A33: 11 | B33: Cantidad de personal de STAFF RUAG | D33: 0 | E33: 0 | F33: 0 | G33: 0 | H33: 0 | I33: 0 | J33: 0 | K33: =AVERAGE(F33:J33) -> 0
A34: 12 | B34: Cantidad de personal de STAFF SUBCONTRATISTA | D34: 0 | E34: 0 | F34: 0 | G34: 0 | H34: 0 | I34: 0 | J34: 0 | K34: =AVERAGE(F34:J34) -> 0
A35: TOTAL TRABAJADORES RUAG | D35: =D31+D33 -> 0 | E35: =E31+E33 -> 0 | F35: =F31+F33 -> 0 | G35: =G31+G33 -> 0 | H35: =H31+H33 -> 0 | I35: =I31+I33 -> 0 | J35: =J31+J33 -> 0 | K35: =K31+K33 -> 0
A36: TOTAL TRABAJADORES SUBCONTRATISTA | D36: =D32+D34 -> 0 | E36: =E32+E34 -> 0 | F36: =F32+F34 -> 0 | G36: =G32+G34 -> 0 | H36: =H32+H34 -> 0 | I36: =I32+I34 -> 0 | J36: =J32+J34 -> 0 | K36: =K32+K34 -> 0
A37: 13 | B37: Total HH personal Obrero RUAG | D37: =D31*8.5 -> 0 | E37: =E31*8.5 -> 0 | F37: =F31*8.5 -> 0 | G37: =G31*8.5 -> 0 | H37: =H31*8.5 -> 0 | I37: =I31*5.5 -> 0 | J37: =J31*5.5 -> 0 | K37: =SUM(F37:J37) -> 0
A38: 14 | B38: Total HH personal Obrero SUBCONTRATISTA | D38: =D32*8.5 -> 0 | E38: =E32*8.5 -> 0 | F38: =F32*8.5 -> 0 | G38: =G32*8.5 -> 0 | H38: =H32*8.5 -> 0 | I38: =I32*5.5 -> 0 | J38: =J32*5.5 -> 0 | K38: =SUM(F38:J38) -> 0
A39: 15 | B39: Total HH personal STAFF RUAG | D39: =D33*8.5 -> 0 | E39: =E33*8.5 -> 0 | F39: =F33*8.5 -> 0 | G39: =G33*8.5 -> 0 | H39: =H33*8.5 -> 0 | I39: =I33*5.5 -> 0 | J39: =J33*5.5 -> 0 | K39: =SUM(F39:J39) -> 0
A40: 16 | B40: Total HH personal STAFF SUBCONTRATISTA | D40: =D34*8.5 -> 0 | E40: =E34*8.5 -> 0 | F40: =F34*8.5 -> 0 | G40: =G34*8.5 -> 0 | H40: =H34*8.5 -> 0 | I40: =I34*5.5 -> 0 | J40: =J34*5.5 -> 0 | K40: =SUM(F40:J40) -> 0
A41: TOTAL HH PRODUCIDAS RUAG | D41: =D37+D39 -> 0 | E41: =E37+E39 -> 0 | F41: =F37+F39 -> 0 | G41: =G37+G39 -> 0 | H41: =H37+H39 -> 0 | I41: =I37+I39 -> 0 | J41: =J37+J39 -> 0 | K41: =K37+K39 -> 0
A42: TOTAL HH PRODUCIDAS SUBCONTRATISTA | D42: =D38+D40 -> 0 | E42: =E38+E40 -> 0 | F42: =F38+F40 -> 0 | G42: =G38+G40 -> 0 | H42: =H38+H40 -> 0 | I42: =I38+I40 -> 0 | J42: =J38+J40 -> 0 | K42: =K38+K40 -> 0
A43: INFORMACIÓN HHT | D43: HORARIO EXTENDIDO
...

Sheet SEMANA 02
C1: REPORTE ESTADÍSTICO SEMANAL SSOMA | J1: CÓDIGO: | K1: SG-SSOMA-03
J2: REVISIÓN: | K2: 03
J3: FECHA: | K3: 46119
J4: PÁGINA: | K4: 01/06
A6: Obra / Proyecto:
A7: Empresa:
A8: Mes - Año: | G8: Semana N°: | I8: 2
A9: Residente de Obra: | G9: Supervisor SSOMA:
A11: HORAS HOMBRE TRABAJADAS
A13: INFORMACIÓN HHT | D13: TURNO DIURNO
D14: Lunes | E14: Martes | F14: Miércoles | G14: Jueves | H14: Viernes | I14: Sábado | J14: Domingo | K14: TOTAL SEMANAL
D15: ='SEMANA 01'!J15+1 -> 46118 | E15: =D15+1 -> 46119 | F15: =E15+1 -> 46120 | G15: =F15+1 -> 46121 | H15: =G15+1 -> 46122 | I15: =H15+1 -> 46123 | J15: =I15+1 -> 46124
A16: 1 | B16: Cantidad de personal obrero RUAG | D16: 0 | E16: 0 | F16: 0 | G16: 0 | H16: 0 | I16: 0 | J16: 0 | K16: =AVERAGE(D16:J16) -> 0
A17: 2 | B17: Cantidad de personal obrero SUBCONTRATISTA | D17: 0 | E17: 0 | F17: 0 | G17: 0 | H17: 0 | I17: 0 | J17: 0 | K17: =AVERAGE(D17:J17) -> 0
A18: 3 | B18: Cantidad de personal de STAFF RUAG | D18: 0 | E18: 0 | F18: 0 | G18: 0 | H18: 0 | I18: 0 | J18: 0 | K18: =AVERAGE(D18:J18) -> 0
A19: 4 | B19: Cantidad de personal de STAFF SUBCONTRATISTA | D19: 0 | E19: 0 | F19: 0 | G19: 0 | H19: 0 | I19: 0 | J19: 0 | K19: =AVERAGE(D19:J19) -> 0
A20: TOTAL TRABAJADORES RUAG | D20: =D16+D18 -> 0 | E20: =E16+E18 -> 0 | F20: =F16+F18 -> 0 | G20: =G16+G18 -> 0 | H20: =H16+H18 -> 0 | I20: =I16+I18 -> 0 | J20: =J16+J18 -> 0 | K20: =K16+K18 -> 0
A21: TOTAL TRABAJADORES SUBCONTRATISTA | D21: =D17+D19 -> 0 | E21: =E17+E19 -> 0 | F21: =F17+F19 -> 0 | G21: =G17+G19 -> 0 | H21: =H17+H19 -> 0 | I21: =I17+I19 -> 0 | J21: =J17+J19 -> 0 | K21: =K17+K19 -> 0
A22: 5 | B22: Total HH personal Obrero RUAG | D22: =D16*8.5 -> 0 | E22: =E16*8.5 -> 0 | F22: =F16*8.5 -> 0 | G22: =G16*8.5 -> 0 | H22: =H16*8.5 -> 0 | I22: =I16*5.5 -> 0 | J22: =J16*5.5 -> 0 | K22: =SUM(D22:J22) -> 0
A23: 6 | B23: Total HH personal Obrero SUBCONTRATISTA | D23: =D17*8.5 -> 0 | E23: =E17*8.5 -> 0 | F23: =F17*8.5 -> 0 | G23: =G17*8.5 -> 0 | H23: =H17*8.5 -> 0 | I23: =I17*5.5 -> 0 | J23: =J17*5.5 -> 0 | K23: =SUM(D23:J23) -> 0
A24: 7 | B24: Total HH personal STAFF RUAG | D24: =D18*8.5 -> 0 | E24: =E18*8.5 -> 0 | F24: =F18*8.5 -> 0 | G24: =G18*8.5 -> 0 | H24: =H18*8.5 -> 0 | I24: =I18*5.5 -> 0 | J24: =J18*5.5 -> 0 | K24: =SUM(D24:J24) -> 0
A25: 8 | B25: Total HH personal STAFF SUBCONTRATISTA | D25: =D19*8.5 -> 0 | E25: =E19*8.5 -> 0 | F25: =F19*8.5 -> 0 | G25: =G19*8.5 -> 0 | H25: =H19*8.5 -> 0 | I25: =I19*5.5 -> 0 | J25: =J19*5.5 -> 0 | K25: =SUM(D25:J25) -> 0
A26: TOTAL HH PRODUCIDAS RUAG | D26: =D22+D24 -> 0 | E26: =E22+E24 -> 0 | F26: =F22+F24 -> 0 | G26: =G22+G24 -> 0 | H26: =H22+H24 -> 0 | I26: =I22+I24 -> 0 | J26: =J22+J24 -> 0 | K26: =K22+K24 -> 0
A27: TOTAL HH PRODUCIDAS SUBCONTRATISTA | D27: =D23+D25 -> 0 | E27: =E23+E25 -> 0 | F27: =F23+F25 -> 0 | G27: =G23+G25 -> 0 | H27: =H23+H25 -> 0 | I27: =I23+I25 -> 0 | J27: =J23+J25 -> 0 | K27: =K23+K25 -> 0
A28: INFORMACIÓN HHT | D28: TURNO NOCTURNO
D29: Lunes | E29: Martes | F29: Miércoles | G29: Jueves | H29: Viernes | I29: Sábado | J29: Domingo | K29: TOTAL SEMANAL
D30: =D15 -> 46118 | E30: =E15 -> 46119 | F30: =F15 -> 46120 | G30: =G15 -> 46121 | H30: =H15 -> 46122 | I30: =I15 -> 46123 | J30: =J15 -> 46124
A31: 9 | B31: Cantidad de personal obrero RUAG | D31: 0 | E31: 0 | F31: 0 | G31: 0 | H31: 0 | I31: 0 | J31: 0 | K31: =AVERAGE(D31:J31) -> 0
A32: 10 | B32: Cantidad de personal obrero SUBCONTRATISTA | D32: 0 | E32: 0 | F32: 0 | G32: 0 | H32: 0 | I32: 0 | J32: 0 | K32: =AVERAGE(D32:J32) -> 0
A33: 11 | B33: Cantidad de personal de STAFF RUAG | D33: 0 | E33: 0 | F33: 0 | G33: 0 | H33: 0 | I33: 0 | J33: 0 | K33: =AVERAGE(D33:J33) -> 0
A34: 12 | B34: Cantidad de personal de STAFF SUBCONTRATISTA | D34: 0 | E34: 0 | F34: 0 | G34: 0 | H34: 0 | I34: 0 | J34: 0 | K34: =AVERAGE(D34:J34) -> 0
A35: TOTAL TRABAJADORES RUAG | D35: =D31+D33 -> 0 | E35: =E31+E33 -> 0 | F35: =F31+F33 -> 0 | G35: =G31+G33 -> 0 | H35: =H31+H33 -> 0 | I35: =I31+I33 -> 0 | J35: =J31+J33 -> 0 | K35: =K31+K33 -> 0
A36: TOTAL TRABAJADORES SUBCONTRATISTA | D36: =D32+D34 -> 0 | E36: =E32+E34 -> 0 | F36: =F32+F34 -> 0 | G36: =G32+G34 -> 0 | H36: =H32+H34 -> 0 | I36: =I32+I34 -> 0 | J36: =J32+J34 -> 0 | K36: =K32+K34 -> 0
A37: 13 | B37: Total HH personal Obrero RUAG | D37: =D31*8.5 -> 0 | E37: =E31*8.5 -> 0 | F37: =F31*8.5 -> 0 | G37: =G31*8.5 -> 0 | H37: =H31*8.5 -> 0 | I37: =I31*5.5 -> 0 | J37: =J31*5.5 -> 0 | K37: =SUM(D37:J37) -> 0
A38: 14 | B38: Total HH personal Obrero SUBCONTRATISTA | D38: =D32*8.5 -> 0 | E38: =E32*8.5 -> 0 | F38: =F32*8.5 -> 0 | G38: =G32*8.5 -> 0 | H38: =H32*8.5 -> 0 | I38: =I32*5.5 -> 0 | J38: =J32*5.5 -> 0 | K38: =SUM(D38:J38) -> 0
A39: 15 | B39: Total HH personal STAFF RUAG | D39: =D33*8.5 -> 0 | E39: =E33*8.5 -> 0 | F39: =F33*8.5 -> 0 | G39: =G33*8.5 -> 0 | H39: =H33*8.5 -> 0 | I39: =I33*5.5 -> 0 | J39: =J33*5.5 -> 0 | K39: =SUM(D39:J39) -> 0
A40: 16 | B40: Total HH personal STAFF SUBCONTRATISTA | D40: =D34*8.5 -> 0 | E40: =E34*8.5 -> 0 | F40: =F34*8.5 -> 0 | G40: =G34*8.5 -> 0 | H40: =H34*8.5 -> 0 | I40: =I34*5.5 -> 0 | J40: =J34*5.5 -> 0 | K40: =SUM(D40:J40) -> 0
A41: TOTAL HH PRODUCIDAS RUAG | D41: =D37+D39 -> 0 | E41: =E37+E39 -> 0 | F41: =F37+F39 -> 0 | G41: =G37+G39 -> 0 | H41: =H37+H39 -> 0 | I41: =I37+I39 -> 0 | J41: =J37+J39 -> 0 | K41: =K37+K39 -> 0
A42: TOTAL HH PRODUCIDAS SUBCONTRATISTA | D42: =D38+D40 -> 0 | E42: =E38+E40 -> 0 | F42: =F38+F40 -> 0 | G42: =G38+G40 -> 0 | H42: =H38+H40 -> 0 | I42: =I38+I40 -> 0 | J42: =J38+J40 -> 0 | K42: =K38+K40 -> 0
A43: INFORMACIÓN HHT | D43: HORARIO EXTENDIDO
...

Sheet SEMANA 03
C1: REPORTE ESTADÍSTICO SEMANAL SSOMA | J1: CÓDIGO: | K1: SG-SSOMA-03
J2: REVISIÓN: | K2: 03
J3: FECHA: | K3: 46119
J4: PÁGINA: | K4: 01/06
A6: Obra / Proyecto:
A7: Empresa:
A8: Mes - Año: | G8: Semana N°: | I8: 3
A9: Residente de Obra: | G9: Supervisor SSOMA:
A11: HORAS HOMBRE TRABAJADAS
A13: INFORMACIÓN HHT | D13: TURNO DIURNO
D14: Lunes | E14: Martes | F14: Miércoles | G14: Jueves | H14: Viernes | I14: Sábado | J14: Domingo | K14: TOTAL SEMANAL
D15: ='SEMANA 02'!J15+1 -> 46125 | E15: =D15+1 -> 46126 | F15: =E15+1 -> 46127 | G15: =F15+1 -> 46128 | H15: =G15+1 -> 46129 | I15: =H15+1 -> 46130 | J15: =I15+1 -> 46131
A16: 1 | B16: Cantidad de personal obrero RUAG | D16: 0 | E16: 0 | F16: 0 | G16: 0 | H16: 0 | I16: 0 | J16: 0 | K16: =AVERAGE(D16:J16) -> 0
A17: 2 | B17: Cantidad de personal obrero SUBCONTRATISTA | D17: 0 | E17: 0 | F17: 0 | G17: 0 | H17: 0 | I17: 0 | J17: 0 | K17: =AVERAGE(D17:J17) -> 0
A18: 3 | B18: Cantidad de personal de STAFF RUAG | D18: 0 | E18: 0 | F18: 0 | G18: 0 | H18: 0 | I18: 0 | J18: 0 | K18: =AVERAGE(D18:J18) -> 0
A19: 4 | B19: Cantidad de personal de STAFF SUBCONTRATISTA | D19: 0 | E19: 0 | F19: 0 | G19: 0 | H19: 0 | I19: 0 | J19: 0 | K19: =AVERAGE(D19:J19) -> 0
A20: TOTAL TRABAJADORES RUAG | D20: =D16+D18 -> 0 | E20: =E16+E18 -> 0 | F20: =F16+F18 -> 0 | G20: =G16+G18 -> 0 | H20: =H16+H18 -> 0 | I20: =I16+I18 -> 0 | J20: =J16+J18 -> 0 | K20: =K16+K18 -> 0
A21: TOTAL TRABAJADORES SUBCONTRATISTA | D21: =D17+D19 -> 0 | E21: =E17+E19 -> 0 | F21: =F17+F19 -> 0 | G21: =G17+G19 -> 0 | H21: =H17+H19 -> 0 | I21: =I17+I19 -> 0 | J21: =J17+J19 -> 0 | K21: =K17+K19 -> 0
A22: 5 | B22: Total HH personal Obrero RUAG | D22: =D16*8.5 -> 0 | E22: =E16*8.5 -> 0 | F22: =F16*8.5 -> 0 | G22: =G16*8.5 -> 0 | H22: =H16*8.5 -> 0 | I22: =I16*5.5 -> 0 | J22: =J16*5.5 -> 0 | K22: =SUM(D22:J22) -> 0
A23: 6 | B23: Total HH personal Obrero SUBCONTRATISTA | D23: =D17*8.5 -> 0 | E23: =E17*8.5 -> 0 | F23: =F17*8.5 -> 0 | G23: =G17*8.5 -> 0 | H23: =H17*8.5 -> 0 | I23: =I17*5.5 -> 0 | J23: =J17*5.5 -> 0 | K23: =SUM(D23:J23) -> 0
A24: 7 | B24: Total HH personal STAFF RUAG | D24: =D18*8.5 -> 0 | E24: =E18*8.5 -> 0 | F24: =F18*8.5 -> 0 | G24: =G18*8.5 -> 0 | H24: =H18*8.5 -> 0 | I24: =I18*5.5 -> 0 | J24: =J18*5.5 -> 0 | K24: =SUM(D24:J24) -> 0
A25: 8 | B25: Total HH personal STAFF SUBCONTRATISTA | D25: =D19*8.5 -> 0 | E25: =E19*8.5 -> 0 | F25: =F19*8.5 -> 0 | G25: =G19*8.5 -> 0 | H25: =H19*8.5 -> 0 | I25: =I19*5.5 -> 0 | J25: =J19*5.5 -> 0 | K25: =SUM(D25:J25) -> 0
A26: TOTAL HH PRODUCIDAS RUAG | D26: =D22+D24 -> 0 | E26: =E22+E24 -> 0 | F26: =F22+F24 -> 0 | G26: =G22+G24 -> 0 | H26: =H22+H24 -> 0 | I26: =I22+I24 -> 0 | J26: =J22+J24 -> 0 | K26: =K22+K24 -> 0
A27: TOTAL HH PRODUCIDAS SUBCONTRATISTA | D27: =D23+D25 -> 0 | E27: =E23+E25 -> 0 | F27: =F23+F25 -> 0 | G27: =G23+G25 -> 0 | H27: =H23+H25 -> 0 | I27: =I23+I25 -> 0 | J27: =J23+J25 -> 0 | K27: =K23+K25 -> 0
A28: INFORMACIÓN HHT | D28: TURNO NOCTURNO
D29: Lunes | E29: Martes | F29: Miércoles | G29: Jueves | H29: Viernes | I29: Sábado | J29: Domingo | K29: TOTAL SEMANAL
D30: =D15 -> 46125 | E30: =E15 -> 46126 | F30: =F15 -> 46127 | G30: =G15 -> 46128 | H30: =H15 -> 46129 | I30: =I15 -> 46130 | J30: =J15 -> 46131
A31: 9 | B31: Cantidad de personal obrero RUAG | D31: 0 | E31: 0 | F31: 0 | G31: 0 | H31: 0 | I31: 0 | J31: 0 | K31: =AVERAGE(D31:J31) -> 0
A32: 10 | B32: Cantidad de personal obrero SUBCONTRATISTA | D32: 0 | E32: 0 | F32: 0 | G32: 0 | H32: 0 | I32: 0 | J32: 0 | K32: =AVERAGE(D32:J32) -> 0
A33: 11 | B33: Cantidad de personal de STAFF RUAG | D33: 0 | E33: 0 | F33: 0 | G33: 0 | H33: 0 | I33: 0 | J33: 0 | K33: =AVERAGE(D33:J33) -> 0
A34: 12 | B34: Cantidad de personal de STAFF SUBCONTRATISTA | D34: 0 | E34: 0 | F34: 0 | G34: 0 | H34: 0 | I34: 0 | J34: 0 | K34: =AVERAGE(D34:J34) -> 0
A35: TOTAL TRABAJADORES RUAG | D35: =D31+D33 -> 0 | E35: =E31+E33 -> 0 | F35: =F31+F33 -> 0 | G35: =G31+G33 -> 0 | H35: =H31+H33 -> 0 | I35: =I31+I33 -> 0 | J35: =J31+J33 -> 0 | K35: =K31+K33 -> 0
A36: TOTAL TRABAJADORES SUBCONTRATISTA | D36: =D32+D34 -> 0 | E36: =E32+E34 -> 0 | F36: =F32+F34 -> 0 | G36: =G32+G34 -> 0 | H36: =H32+H34 -> 0 | I36: =I32+I34 -> 0 | J36: =J32+J34 -> 0 | K36: =K32+K34 -> 0
A37: 13 | B37: Total HH personal Obrero RUAG | D37: =D31*8.5 -> 0 | E37: =E31*8.5 -> 0 | F37: =F31*8.5 -> 0 | G37: =G31*8.5 -> 0 | H37: =H31*8.5 -> 0 | I37: =I31*5.5 -> 0 | J37: =J31*5.5 -> 0 | K37: =SUM(D37:J37) -> 0
A38: 14 | B38: Total HH personal Obrero SUBCONTRATISTA | D38: =D32*8.5 -> 0 | E38: =E32*8.5 -> 0 | F38: =F32*8.5 -> 0 | G38: =G32*8.5 -> 0 | H38: =H32*8.5 -> 0 | I38: =I32*5.5 -> 0 | J38: =J32*5.5 -> 0 | K38: =SUM(D38:J38) -> 0
A39: 15 | B39: Total HH personal STAFF RUAG | D39: =D33*8.5 -> 0 | E39: =E33*8.5 -> 0 | F39: =F33*8.5 -> 0 | G39: =G33*8.5 -> 0 | H39: =H33*8.5 -> 0 | I39: =I33*5.5 -> 0 | J39: =J33*5.5 -> 0 | K39: =SUM(D39:J39) -> 0
A40: 16 | B40: Total HH personal STAFF SUBCONTRATISTA | D40: =D34*8.5 -> 0 | E40: =E34*8.5 -> 0 | F40: =F34*8.5 -> 0 | G40: =G34*8.5 -> 0 | H40: =H34*8.5 -> 0 | I40: =I34*5.5 -> 0 | J40: =J34*5.5 -> 0 | K40: =SUM(D40:J40) -> 0
A41: TOTAL HH PRODUCIDAS RUAG | D41: =D37+D39 -> 0 | E41: =E37+E39 -> 0 | F41: =F37+F39 -> 0 | G41: =G37+G39 -> 0 | H41: =H37+H39 -> 0 | I41: =I37+I39 -> 0 | J41: =J37+J39 -> 0 | K41: =K37+K39 -> 0
A42: TOTAL HH PRODUCIDAS SUBCONTRATISTA | D42: =D38+D40 -> 0 | E42: =E38+E40 -> 0 | F42: =F38+F40 -> 0 | G42: =G38+G40 -> 0 | H42: =H38+H40 -> 0 | I42: =I38+I40 -> 0 | J42: =J38+J40 -> 0 | K42: =K38+K40 -> 0
A43: INFORMACIÓN HHT | D43: HORARIO EXTENDIDO
...

Sheet SEMANA 04
C1: REPORTE ESTADÍSTICO SEMANAL SSOMA | J1: CÓDIGO: | K1: SG-SSOMA-03
J2: REVISIÓN: | K2: 03
J3: FECHA: | K3: 46119
J4: PÁGINA: | K4: 01/06
A6: Obra / Proyecto:
A7: Empresa:
A8: Mes - Año: | G8: Semana N°: | I8: 4
A9: Residente de Obra: | G9: Supervisor SSOMA:
A11: HORAS HOMBRE TRABAJADAS
A13: INFORMACIÓN HHT | D13: TURNO DIURNO
D14: Lunes | E14: Martes | F14: Miércoles | G14: Jueves | H14: Viernes | I14: Sábado | J14: Domingo | K14: TOTAL SEMANAL
D15: ='SEMANA 03'!J15+1 -> 46132 | E15: =D15+1 -> 46133 | F15: =E15+1 -> 46134 | G15: =F15+1 -> 46135 | H15: =G15+1 -> 46136 | I15: =H15+1 -> 46137 | J15: =I15+1 -> 46138
A16: 1 | B16: Cantidad de personal obrero RUAG | D16: 0 | E16: 0 | F16: 0 | G16: 0 | H16: 0 | I16: 0 | J16: 0 | K16: =AVERAGE(D16:J16) -> 0
A17: 2 | B17: Cantidad de personal obrero SUBCONTRATISTA | D17: 0 | E17: 0 | F17: 0 | G17: 0 | H17: 0 | I17: 0 | J17: 0 | K17: =AVERAGE(D17:J17) -> 0
A18: 3 | B18: Cantidad de personal de STAFF RUAG | D18: 0 | E18: 0 | F18: 0 | G18: 0 | H18: 0 | I18: 0 | J18: 0 | K18: =AVERAGE(D18:J18) -> 0
A19: 4 | B19: Cantidad de personal de STAFF SUBCONTRATISTA | D19: 0 | E19: 0 | F19: 0 | G19: 0 | H19: 0 | I19: 0 | J19: 0 | K19: =AVERAGE(D19:J19) -> 0
A20: TOTAL TRABAJADORES RUAG | D20: =D16+D18 -> 0 | E20: =E16+E18 -> 0 | F20: =F16+F18 -> 0 | G20: =G16+G18 -> 0 | H20: =H16+H18 -> 0 | I20: =I16+I18 -> 0 | J20: =J16+J18 -> 0 | K20: =K16+K18 -> 0
A21: TOTAL TRABAJADORES SUBCONTRATISTA | D21: =D17+D19 -> 0 | E21: =E17+E19 -> 0 | F21: =F17+F19 -> 0 | G21: =G17+G19 -> 0 | H21: =H17+H19 -> 0 | I21: =I17+I19 -> 0 | J21: =J17+J19 -> 0 | K21: =K17+K19 -> 0
A22: 5 | B22: Total HH personal Obrero RUAG | D22: =D16*8.5 -> 0 | E22: =E16*8.5 -> 0 | F22: =F16*8.5 -> 0 | G22: =G16*8.5 -> 0 | H22: =H16*8.5 -> 0 | I22: =I16*5.5 -> 0 | J22: =J16*5.5 -> 0 | K22: =SUM(D22:J22) -> 0
A23: 6 | B23: Total HH personal Obrero SUBCONTRATISTA | D23: =D17*8.5 -> 0 | E23: =E17*8.5 -> 0 | F23: =F17*8.5 -> 0 | G23: =G17*8.5 -> 0 | H23: =H17*8.5 -> 0 | I23: =I17*5.5 -> 0 | J23: =J17*5.5 -> 0 | K23: =SUM(D23:J23) -> 0
A24: 7 | B24: Total HH personal STAFF RUAG | D24: =D18*8.5 -> 0 | E24: =E18*8.5 -> 0 | F24: =F18*8.5 -> 0 | G24: =G18*8.5 -> 0 | H24: =H18*8.5 -> 0 | I24: =I18*5.5 -> 0 | J24: =J18*5.5 -> 0 | K24: =SUM(D24:J24) -> 0
A25: 8 | B25: Total HH personal STAFF SUBCONTRATISTA | D25: =D19*8.5 -> 0 | E25: =E19*8.5 -> 0 | F25: =F19*8.5 -> 0 | G25: =G19*8.5 -> 0 | H25: =H19*8.5 -> 0 | I25: =I19*5.5 -> 0 | J25: =J19*5.5 -> 0 | K25: =SUM(D25:J25) -> 0
A26: TOTAL HH PRODUCIDAS RUAG | D26: =D22+D24 -> 0 | E26: =E22+E24 -> 0 | F26: =F22+F24 -> 0 | G26: =G22+G24 -> 0 | H26: =H22+H24 -> 0 | I26: =I22+I24 -> 0 | J26: =J22+J24 -> 0 | K26: =K22+K24 -> 0
A27: TOTAL HH PRODUCIDAS SUBCONTRATISTA | D27: =D23+D25 -> 0 | E27: =E23+E25 -> 0 | F27: =F23+F25 -> 0 | G27: =G23+G25 -> 0 | H27: =H23+H25 -> 0 | I27: =I23+I25 -> 0 | J27: =J23+J25 -> 0 | K27: =K23+K25 -> 0
A28: INFORMACIÓN HHT | D28: TURNO NOCTURNO
D29: Lunes | E29: Martes | F29: Miércoles | G29: Jueves | H29: Viernes | I29: Sábado | J29: Domingo | K29: TOTAL SEMANAL
D30: =D15 -> 46132 | E30: =E15 -> 46133 | F30: =F15 -> 46134 | G30: =G15 -> 46135 | H30: =H15 -> 46136 | I30: =I15 -> 46137 | J30: =J15 -> 46138
A31: 9 | B31: Cantidad de personal obrero RUAG | D31: 0 | E31: 0 | F31: 0 | G31: 0 | H31: 0 | I31: 0 | J31: 0 | K31: =AVERAGE(D31:J31) -> 0
A32: 10 | B32: Cantidad de personal obrero SUBCONTRATISTA | D32: 0 | E32: 0 | F32: 0 | G32: 0 | H32: 0 | I32: 0 | J32: 0 | K32: =AVERAGE(D32:J32) -> 0
A33: 11 | B33: Cantidad de personal de STAFF RUAG | D33: 0 | E33: 0 | F33: 0 | G33: 0 | H33: 0 | I33: 0 | J33: 0 | K33: =AVERAGE(D33:J33) -> 0
A34: 12 | B34: Cantidad de personal de STAFF SUBCONTRATISTA | D34: 0 | E34: 0 | F34: 0 | G34: 0 | H34: 0 | I34: 0 | J34: 0 | K34: =AVERAGE(D34:J34) -> 0
A35: TOTAL TRABAJADORES RUAG | D35: =D31+D33 -> 0 | E35: =E31+E33 -> 0 | F35: =F31+F33 -> 0 | G35: =G31+G33 -> 0 | H35: =H31+H33 -> 0 | I35: =I31+I33 -> 0 | J35: =J31+J33 -> 0 | K35: =K31+K33 -> 0
A36: TOTAL TRABAJADORES SUBCONTRATISTA | D36: =D32+D34 -> 0 | E36: =E32+E34 -> 0 | F36: =F32+F34 -> 0 | G36: =G32+G34 -> 0 | H36: =H32+H34 -> 0 | I36: =I32+I34 -> 0 | J36: =J32+J34 -> 0 | K36: =K32+K34 -> 0
A37: 13 | B37: Total HH personal Obrero RUAG | D37: =D31*8.5 -> 0 | E37: =E31*8.5 -> 0 | F37: =F31*8.5 -> 0 | G37: =G31*8.5 -> 0 | H37: =H31*8.5 -> 0 | I37: =I31*5.5 -> 0 | J37: =J31*5.5 -> 0 | K37: =SUM(D37:J37) -> 0
A38: 14 | B38: Total HH personal Obrero SUBCONTRATISTA | D38: =D32*8.5 -> 0 | E38: =E32*8.5 -> 0 | F38: =F32*8.5 -> 0 | G38: =G32*8.5 -> 0 | H38: =H32*8.5 -> 0 | I38: =I32*5.5 -> 0 | J38: =J32*5.5 -> 0 | K38: =SUM(D38:J38) -> 0
A39: 15 | B39: Total HH personal STAFF RUAG | D39: =D33*8.5 -> 0 | E39: =E33*8.5 -> 0 | F39: =F33*8.5 -> 0 | G39: =G33*8.5 -> 0 | H39: =H33*8.5 -> 0 | I39: =I33*5.5 -> 0 | J39: =J33*5.5 -> 0 | K39: =SUM(D39:J39) -> 0
A40: 16 | B40: Total HH personal STAFF SUBCONTRATISTA | D40: =D34*8.5 -> 0 | E40: =E34*8.5 -> 0 | F40: =F34*8.5 -> 0 | G40: =G34*8.5 -> 0 | H40: =H34*8.5 -> 0 | I40: =I34*5.5 -> 0 | J40: =J34*5.5 -> 0 | K40: =SUM(D40:J40) -> 0
A41: TOTAL HH PRODUCIDAS RUAG | D41: =D37+D39 -> 0 | E41: =E37+E39 -> 0 | F41: =F37+F39 -> 0 | G41: =G37+G39 -> 0 | H41: =H37+H39 -> 0 | I41: =I37+I39 -> 0 | J41: =J37+J39 -> 0 | K41: =K37+K39 -> 0
A42: TOTAL HH PRODUCIDAS SUBCONTRATISTA | D42: =D38+D40 -> 0 | E42: =E38+E40 -> 0 | F42: =F38+F40 -> 0 | G42: =G38+G40 -> 0 | H42: =H38+H40 -> 0 | I42: =I38+I40 -> 0 | J42: =J38+J40 -> 0 | K42: =K38+K40 -> 0
A43: INFORMACIÓN HHT | D43: HORARIO EXTENDIDO
...

Sheet SEMANA 05
C1: REPORTE ESTADÍSTICO SEMANAL SSOMA | J1: CÓDIGO: | K1: SG-SSOMA-03
J2: REVISIÓN: | K2: 03
J3: FECHA: | K3: 46119
J4: PÁGINA: | K4: 01/06
A6: Obra / Proyecto:
A7: Empresa:
A8: Mes - Año: | G8: Semana N°: | I8: 5
A9: Residente de Obra: | G9: Supervisor SSOMA:
A11: HORAS HOMBRE TRABAJADAS
A13: INFORMACIÓN HHT | D13: TURNO DIURNO
D14: Lunes | E14: Martes | F14: Miércoles | G14: Jueves | H14: Viernes | I14: Sábado | J14: Domingo | K14: TOTAL SEMANAL
D15: ='SEMANA 04'!J15+1 -> 46139 | E15: =D15+1 -> 46140 | F15: =E15+1 -> 46141 | G15: =F15+1 -> 46142
A16: 1 | B16: Cantidad de personal obrero RUAG | D16: 0 | E16: 0 | F16: 0 | G16: 0 | H16: 0 | I16: 0 | J16: 0 | K16: =AVERAGE(D16:G16) -> 0
A17: 2 | B17: Cantidad de personal obrero SUBCONTRATISTA | D17: 0 | E17: 0 | F17: 0 | G17: 0 | H17: 0 | I17: 0 | J17: 0 | K17: =AVERAGE(D17:G17) -> 0
A18: 3 | B18: Cantidad de personal de STAFF RUAG | D18: 0 | E18: 0 | F18: 0 | G18: 0 | H18: 0 | I18: 0 | J18: 0 | K18: =AVERAGE(D18:G18) -> 0
A19: 4 | B19: Cantidad de personal de STAFF SUBCONTRATISTA | D19: 0 | E19: 0 | F19: 0 | G19: 0 | H19: 0 | I19: 0 | J19: 0 | K19: =AVERAGE(D19:G19) -> 0
A20: TOTAL TRABAJADORES RUAG | D20: =D16+D18 -> 0 | E20: =E16+E18 -> 0 | F20: =F16+F18 -> 0 | G20: =G16+G18 -> 0 | H20: =H16+H18 -> 0 | I20: =I16+I18 -> 0 | J20: =J16+J18 -> 0 | K20: =K16+K18 -> 0
A21: TOTAL TRABAJADORES SUBCONTRATISTA | D21: =D17+D19 -> 0 | E21: =E17+E19 -> 0 | F21: =F17+F19 -> 0 | G21: =G17+G19 -> 0 | H21: =H17+H19 -> 0 | I21: =I17+I19 -> 0 | J21: =J17+J19 -> 0 | K21: =K17+K19 -> 0
A22: 5 | B22: Total HH personal Obrero RUAG | D22: =D16*8.5 -> 0 | E22: =E16*8.5 -> 0 | F22: =F16*8.5 -> 0 | G22: =G16*8.5 -> 0 | H22: =H16*8.5 -> 0 | I22: =I16*5.5 -> 0 | J22: =J16*5.5 -> 0 | K22: =SUM(D22:J22) -> 0
A23: 6 | B23: Total HH personal Obrero SUBCONTRATISTA | D23: =D17*8.5 -> 0 | E23: =E17*8.5 -> 0 | F23: =F17*8.5 -> 0 | G23: =G17*8.5 -> 0 | H23: =H17*8.5 -> 0 | I23: =I17*5.5 -> 0 | J23: =J17*5.5 -> 0 | K23: =SUM(D23:J23) -> 0
A24: 7 | B24: Total HH personal STAFF RUAG | D24: =D18*8.5 -> 0 | E24: =E18*8.5 -> 0 | F24: =F18*8.5 -> 0 | G24: =G18*8.5 -> 0 | H24: =H18*8.5 -> 0 | I24: =I18*5.5 -> 0 | J24: =J18*5.5 -> 0 | K24: =SUM(D24:J24) -> 0
A25: 8 | B25: Total HH personal STAFF SUBCONTRATISTA | D25: =D19*8.5 -> 0 | E25: =E19*8.5 -> 0 | F25: =F19*8.5 -> 0 | G25: =G19*8.5 -> 0 | H25: =H19*8.5 -> 0 | I25: =I19*5.5 -> 0 | J25: =J19*5.5 -> 0 | K25: =SUM(D25:J25) -> 0
A26: TOTAL HH PRODUCIDAS RUAG | D26: =D22+D24 -> 0 | E26: =E22+E24 -> 0 | F26: =F22+F24 -> 0 | G26: =G22+G24 -> 0 | H26: =H22+H24 -> 0 | I26: =I22+I24 -> 0 | J26: =J22+J24 -> 0 | K26: =K22+K24 -> 0
A27: TOTAL HH PRODUCIDAS SUBCONTRATISTA | D27: =D23+D25 -> 0 | E27: =E23+E25 -> 0 | F27: =F23+F25 -> 0 | G27: =G23+G25 -> 0 | H27: =H23+H25 -> 0 | I27: =I23+I25 -> 0 | J27: =J23+J25 -> 0 | K27: =K23+K25 -> 0
A28: INFORMACIÓN HHT | D28: TURNO NOCTURNO
D29: Lunes | E29: Martes | F29: Miércoles | G29: Jueves | H29: Viernes | I29: Sábado | J29: Domingo | K29: TOTAL SEMANAL
D30: =D15 -> 46139 | E30: =E15 -> 46140 | F30: =F15 -> 46141 | G30: =G15 -> 46142
A31: 9 | B31: Cantidad de personal obrero RUAG | D31: 0 | E31: 0 | F31: 0 | G31: 0 | H31: 0 | I31: 0 | J31: 0 | K31: =AVERAGE(D31:G31) -> 0
A32: 10 | B32: Cantidad de personal obrero SUBCONTRATISTA | D32: 0 | E32: 0 | F32: 0 | G32: 0 | H32: 0 | I32: 0 | J32: 0 | K32: =AVERAGE(D32:G32) -> 0
A33: 11 | B33: Cantidad de personal de STAFF RUAG | D33: 0 | E33: 0 | F33: 0 | G33: 0 | H33: 0 | I33: 0 | J33: 0 | K33: =AVERAGE(D33:G33) -> 0
A34: 12 | B34: Cantidad de personal de STAFF SUBCONTRATISTA | D34: 0 | E34: 0 | F34: 0 | G34: 0 | H34: 0 | I34: 0 | J34: 0 | K34: =AVERAGE(D34:G34) -> 0
A35: TOTAL TRABAJADORES RUAG | D35: =D31+D33 -> 0 | E35: =E31+E33 -> 0 | F35: =F31+F33 -> 0 | G35: =G31+G33 -> 0 | H35: =H31+H33 -> 0 | I35: =I31+I33 -> 0 | J35: =J31+J33 -> 0 | K35: =K31+K33 -> 0
A36: TOTAL TRABAJADORES SUBCONTRATISTA | D36: =D32+D34 -> 0 | E36: =E32+E34 -> 0 | F36: =F32+F34 -> 0 | G36: =G32+G34 -> 0 | H36: =H32+H34 -> 0 | I36: =I32+I34 -> 0 | J36: =J32+J34 -> 0 | K36: =K32+K34 -> 0
A37: 13 | B37: Total HH personal Obrero RUAG | D37: =D31*8.5 -> 0 | E37: =E31*8.5 -> 0 | F37: =F31*8.5 -> 0 | G37: =G31*8.5 -> 0 | H37: =H31*8.5 -> 0 | I37: =I31*5.5 -> 0 | J37: =J31*5.5 -> 0 | K37: =SUM(D37:J37) -> 0
A38: 14 | B38: Total HH personal Obrero SUBCONTRATISTA | D38: =D32*8.5 -> 0 | E38: =E32*8.5 -> 0 | F38: =F32*8.5 -> 0 | G38: =G32*8.5 -> 0 | H38: =H32*8.5 -> 0 | I38: =I32*5.5 -> 0 | J38: =J32*5.5 -> 0 | K38: =SUM(D38:J38) -> 0
A39: 15 | B39: Total HH personal STAFF RUAG | D39: =D33*8.5 -> 0 | E39: =E33*8.5 -> 0 | F39: =F33*8.5 -> 0 | G39: =G33*8.5 -> 0 | H39: =H33*8.5 -> 0 | I39: =I33*5.5 -> 0 | J39: =J33*5.5 -> 0 | K39: =SUM(D39:J39) -> 0
A40: 16 | B40: Total HH personal STAFF SUBCONTRATISTA | D40: =D34*8.5 -> 0 | E40: =E34*8.5 -> 0 | F40: =F34*8.5 -> 0 | G40: =G34*8.5 -> 0 | H40: =H34*8.5 -> 0 | I40: =I34*5.5 -> 0 | J40: =J34*5.5 -> 0 | K40: =SUM(D40:J40) -> 0
A41: TOTAL HH PRODUCIDAS RUAG | D41: =D37+D39 -> 0 | E41: =E37+E39 -> 0 | F41: =F37+F39 -> 0 | G41: =G37+G39 -> 0 | H41: =H37+H39 -> 0 | I41: =I37+I39 -> 0 | J41: =J37+J39 -> 0 | K41: =K37+K39 -> 0
A42: TOTAL HH PRODUCIDAS SUBCONTRATISTA | D42: =D38+D40 -> 0 | E42: =E38+E40 -> 0 | F42: =F38+F40 -> 0 | G42: =G38+G40 -> 0 | H42: =H38+H40 -> 0 | I42: =I38+I40 -> 0 | J42: =J38+J40 -> 0 | K42: =K38+K40 -> 0
A43: INFORMACIÓN HHT | D43: HORARIO EXTENDIDO
...

Sheet  CONS
C1: REPORTE ESTADÍSTICO SSOMA MENSUAL | H1: CÓDIGO: | I1: SG-SSOMA-03
H2: REVISIÓN: | I2: 03
H3: FECHA: | I3: 46119
H4: PÁGINA: | I4: 06/06
A5: Obra / Proyecto:
A6: Empresa:
A7: Mes: | C7: ABRIL 2026
A8: CONSOLIDADO
D10: SEMANA 1 | E10: SEMANA 2 | F10: SEMANA 3 | G10: SEMANA 4 | H10: SEMANA 5 | I10: TOTAL MENSUAL
A11: N° | B11: Información
A12: INFORMACIÓN DE HHT
A13: TOTAL TRABAJADORES RUAG | D13: ='SEMANA 01'!K65 -> 0 | E13: ='SEMANA 02'!K65 -> 0 | F13: ='SEMANA 03'!K65 -> 0 | G13: ='SEMANA 04'!K65 -> 0 | H13: ='SEMANA 05'!K65 -> 0 | I13: =MAX(D13:H13) -> 0
A14: TOTAL HH PRODUCIDAS RUAG | D14: ='SEMANA 01'!K71 -> 0 | E14: ='SEMANA 02'!K71 -> 0 | F14: ='SEMANA 03'!K71 -> 0 | G14: ='SEMANA 04'!K71 -> 0 | H14: ='SEMANA 05'!K71 -> 0 | I14: =SUM(D14:H14) -> 0
A15: TOTAL TRABAJADORES SUBCONTRATISTA | D15: ='SEMANA 01'!K66 -> 0 | E15: ='SEMANA 02'!K66 -> 0 | F15: ='SEMANA 03'!K66 -> 0 | G15: ='SEMANA 04'!K66 -> 0 | H15: ='SEMANA 05'!K66 -> 0 | I15: =MAX(D15:H15) -> 0
A16: TOTAL HH PRODUCIDAS SUBCONTRATISTA | D16: ='SEMANA 01'!K72 -> 0 | E16: ='SEMANA 02'!K72 -> 0 | F16: ='SEMANA 03'!K72 -> 0 | G16: ='SEMANA 04'!K72 -> 0 | H16: ='SEMANA 05'!K72 -> 0 | I16: =SUM(D16:H16) -> 0
A17: INFORMACIÓN DE ACCIDENTES
A18: TOTAL ACCIDENTES LEVES | D18: ='SEMANA 01'!K134 -> 0 | E18: ='SEMANA 02'!K134 -> 0 | F18: ='SEMANA 03'!K134 -> 0 | G18: ='SEMANA 04'!K134 -> 0 | H18: ='SEMANA 05'!K134 -> 0 | I18: =SUM(D18:H18) -> 0
A19: TOTAL ACCIDENTES INCAPACITANTES | D19: ='SEMANA 01'!K135 -> 0 | E19: ='SEMANA 02'!K135 -> 0 | F19: ='SEMANA 03'!K135 -> 0 | G19: ='SEMANA 04'!K135 -> 0 | H19: ='SEMANA 05'!K135 -> 0 | I19: =SUM(D19:H19) -> 0
A20: TOTAL ACCIDENTES MORTALES | D20: ='SEMANA 01'!K136 -> 0 | E20: ='SEMANA 02'!K136 -> 0 | F20: ='SEMANA 03'!K136 -> 0 | G20: ='SEMANA 04'!K136 -> 0 | H20: ='SEMANA 05'!K136 -> 0 | I20: =SUM(D20:H20) -> 0
A21: TOTAL DE ACCIDENTES DEL MES | I21: =SUM(I18:I20) -> 0
A22: INFORMACIÓN DE DÍAS PERDIDOS
A23: TOTAL DÍAS PERDIDOS | D23: ='SEMANA 01'!K140 -> 0 | E23: ='SEMANA 02'!K140 -> 0 | F23: ='SEMANA 03'!K140 -> 0 | G23: ='SEMANA 04'!K140 -> 0 | H23: ='SEMANA 05'!K140 -> 0 | I23: =SUM(D23:H23) -> 0
A24: INFORMACIÓN DE INCIDENTES
A25: TOTAL INCIDENTES | D25: ='SEMANA 01'!K144 -> 0 | E25: ='SEMANA 02'!K144 -> 0 | F25: ='SEMANA 03'!K144 -> 0 | G25: ='SEMANA 04'!K144 -> 0 | H25: ='SEMANA 05'!K144 -> 0 | I25: =SUM(D25:H25) -> 0
A26: TOTAL INCIDENTES PELIGROSOS | D26: ='SEMANA 01'!K145 -> 0 | E26: ='SEMANA 02'!K145 -> 0 | F26: ='SEMANA 03'!K145 -> 0 | G26: ='SEMANA 04'!K145 -> 0 | H26: ='SEMANA 05'!K145 -> 0 | I26: =SUM(D26:H26) -> 0
A27: INFORMACIÓN DE AMONESTACIONES
A28: TOTAL AMONESTACIONES RUAG | D28: ='SEMANA 01'!K158 -> 0 | E28: ='SEMANA 02'!K158 -> 0 | F28: ='SEMANA 03'!K158 -> 0 | G28: ='SEMANA 04'!K158 -> 0 | H28: ='SEMANA 05'!K158 -> 0 | I28: =SUM(D28:H28) -> 0
A29: TOTAL AMONESTACIONES SUBCONTRATISTA | D29: ='SEMANA 01'!K159 -> 0 | E29: ='SEMANA 02'!K159 -> 0 | F29: ='SEMANA 03'!K159 -> 0 | G29: ='SEMANA 04'!K159 -> 0 | H29: ='SEMANA 05'!K159 -> 0 | I29: =SUM(D29:H29) -> 0
A30: NÚMERO GENERADO DE DOCUMENTOS DE GESTIÓN
A31: 1 | B31: ATS RUAG | D31: ='SEMANA 01'!K171 -> 0 | E31: ='SEMANA 02'!K171 -> 0 | F31: ='SEMANA 03'!K171 -> 0 | G31: ='SEMANA 04'!K171 -> 0 | H31: ='SEMANA 05'!K171 -> 0 | I31: =SUM(D31:H31) -> 0
A32: 2 | B32: ATS SUBCONTRATISTA | D32: ='SEMANA 01'!K172 -> 0 | E32: ='SEMANA 02'!K172 -> 0 | F32: ='SEMANA 03'!K172 -> 0 | G32: ='SEMANA 04'!K172 -> 0 | H32: ='SEMANA 05'!K172 -> 0 | I32: =SUM(D32:H32) -> 0
A33: 3 | B33: PERMISOS DE TRABAJO EN ALTURA | D33: ='SEMANA 01'!K173 -> 0 | E33: ='SEMANA 02'!K173 -> 0 | F33: ='SEMANA 03'!K173 -> 0 | G33: ='SEMANA 04'!K173 -> 0 | H33: ='SEMANA 05'!K173 -> 0 | I33: =SUM(D33:H33) -> 0
A34: 4 | B34: PERMISOS DE TRABAJO EN ALTURA | D34: ='SEMANA 01'!K174 -> 0 | E34: ='SEMANA 02'!K174 -> 0 | F34: ='SEMANA 03'!K174 -> 0 | G34: ='SEMANA 04'!K174 -> 0 | H34: ='SEMANA 05'!K174 -> 0 | I34: =SUM(D34:H34) -> 0
A35: 5 | B35: PERMISOS DE TRABAJO EN CALIENTE | D35: ='SEMANA 01'!K175 -> 0 | E35: ='SEMANA 02'!K175 -> 0 | F35: ='SEMANA 03'!K175 -> 0 | G35: ='SEMANA 04'!K175 -> 0 | H35: ='SEMANA 05'!K175 -> 0 | I35: =SUM(D35:H35) -> 0
A36: 6 | B36: PERMISOS DE TRABAJO EN CALIENTE | D36: ='SEMANA 01'!K176 -> 0 | E36: ='SEMANA 02'!K176 -> 0 | F36: ='SEMANA 03'!K176 -> 0 | G36: ='SEMANA 04'!K176 -> 0 | H36: ='SEMANA 05'!K176 -> 0 | I36: =SUM(D36:H36) -> 0
A37: 7 | B37: PERMISOS DE HORARIO EXTENDIDO | D37: ='SEMANA 01'!K177 -> 0 | E37: ='SEMANA 02'!K177 -> 0 | F37: ='SEMANA 03'!K177 -> 0 | G37: ='SEMANA 04'!K177 -> 0 | H37: ='SEMANA 05'!K177 -> 0 | I37: =SUM(D37:H37) -> 0
A38: 8 | B38: PERMISOS DE HORARIO EXTENDIDO | D38: ='SEMANA 01'!K178 -> 0 | E38: ='SEMANA 02'!K178 -> 0 | F38: ='SEMANA 03'!K178 -> 0 | G38: ='SEMANA 04'!K178 -> 0 | H38: ='SEMANA 05'!K178 -> 0 | I38: =SUM(D38:H38) -> 0
A39: 9 | D39: =+'SEMANA 01'!K182 -> 0 | E39: ='SEMANA 02'!K179 -> 0 | F39: ='SEMANA 03'!K179 -> 0 | G39: ='SEMANA 04'!K179 -> 0 | H39: ='SEMANA 05'!K179 -> 0 | I39: =SUM(D39:H39) -> 0
A40: 10 | D40: =+'SEMANA 01'!K184 -> 0 | E40: ='SEMANA 02'!K180 -> 0 | F40: ='SEMANA 03'!K180 -> 0 | G40: ='SEMANA 04'!K180 -> 0 | H40: ='SEMANA 05'!K180 -> 0 | I40: =SUM(D40:H40) -> 0
A41: 11 | D41: =+'SEMANA 01'!K185 -> 0 | E41: ='SEMANA 02'!K181 -> 0 | F41: ='SEMANA 03'!K181 -> 0 | G41: ='SEMANA 04'!K181 -> 0 | H41: ='SEMANA 05'!K181 -> 0 | I41: =SUM(D41:H41) -> 0
...

Sheet Hoja1
C16: Tipos de materiales no peligrosos | D16: Tipos de materiales peligrosos
C17: Plástico | D17: Trapos o waypes con hidrocarburos, pintura u otro producto químico peligroso.
C18: Papel/ cartón | D18: Envases con hidrocarburos, pintura u otro producto químico peligroso.
C19: Metal | D19: Toners
C20: Vidrio | D20: Tintas
C21: Orgánico | D21: Fluorescentes
C22: Telas | D22: Focos ahorradores
C23: Desmonte | D23: Pilas
C24: Residuos de baño | D24: Baterías
C25: Tecnopor | D25: Residuos Biocontaminados como mascarillas KN95, mascarillas quirúrgicas, mascarillas de tela, guantes de latex, careta facial, residuos de tópico
